Workbook

Sheet How to use
A1: How to use this Gantt chart
A2: 1. Each Friday, fill in the yellow cells on the Gantt sheet: actual start, actual end and % complete for anything you worked on.
A3: 2. Typing 100% in % complete ticks the task off (✓) and colours its status green.
A4: 3. Status updates by itself from today's date: Not started, On track, Behind (less done than the time used suggests), Late (past the planned end), Done.
A5: 4. If a task slips, change its Planned start and end, write the reason in Notes, and add a row to the Change log. Never edit the Baseline columns: they are the original plan the mid-term review compares against.
A6: 5. Slip vs baseline shows, in weeks, how far each task has moved from the original plan (red when late).
A7: 6. Critical tasks (red bars) have no float: if one slips, the tasks after it slip too. Non-critical tasks (grey) can use their float (hatched) without delaying the project.
A8: 7. ● marks the weeks you actually worked on a task (from Actual start to Actual end, or to today if it is still running). ◆ marks a milestone.
A9: 8. Week 1 starts on Monday 19 October 2026. Assessment dates (mid-term, report, demonstration) are planned dates: confirm them on Blackboard under Assessment Feedback and update the milestones.
A10: 9. For the mid-term review, print or screenshot the Gantt sheet with the Change log: together they are the original and revised plan the handbook asks for.

Sheet Gantt
A1: EE3EPJ Project Gantt Chart: AdaptEnergy (Adaptive Closed-Loop Home Energy Controller)
A2: Oluwatomisin Agbaje · 240369394 · Supervisors: Dr Faisal M Shah, Dr Andrew Cross · baseline agreed 23 Oct 2026
B3: Week 1 starts (Monday) | D3: 46314 | G3: Current week | I3: =INT((D4-D3)/7)+1 -> 1 | K3: Tasks behind or late | N3: =COUNTIF(P8:P78,"Behind")+COUNTIF(P8:P78,"Late")+COUNTIF(P8:P78,"Overdue") -> 6
B4: Today | D4: =TODAY() -> 46318 | G4: Overall progress | I4: =IFERROR(SUMIFS(S8:S78,C8:C78,"Task")/SUMIFS(K8:K78,C8:C78,"Task"),0) -> 0 | K4: Milestones done | N4: =COUNTIFS(C8:C78,"Milestone",R8:R78,"✓")&" of "&COUNTIF(C8:C78,"Milestone") -> 1 of 14
U5: Week number (top) and Monday date (below). ● = actual work, ◆ = milestone
A6: ID | B6: Task | C6: Type | D6: Objective | E6: Depends on | F6: Critical? | G6: Baseline start | H6: Baseline end | I6: Planned start | J6: Planned end | K6: Duration (wks) | L6: Float (wks) | M6: Actual start | N6: Actual end | O6: % complete | P6: Status | Q6: Slip vs baseline (wks) | R6: Done | S6: Earned (wks) | T6: Notes / reason for change | U6: 1 | V6: 2 | W6: 3 | X6: 4 | Y6: 5 | Z6: 6 | AA6: 7 | AB6: 8 | AC6: 9 | AD6: 10 | AE6: 11 | AF6: 12 | AG6: 13 | AH6: 14 | AI6: 15 | AJ6: 16 | AK6: 17 | AL6: 18 | AM6: 19 | AN6: 20 | AO6: 21 | AP6: 22 | AQ6: 23 | AR6: 24 | AS6: 25 | AT6: 26 | AU6: 27 | AV6: 28 | AW6: 29 | AX6: 30 | AY6: 31 | AZ6: 32
U7: =$D$3+7*(U$6-1) -> 46314 | V7: =$D$3+7*(V$6-1) -> 46321 | W7: =$D$3+7*(W$6-1) -> 46328 | X7: =$D$3+7*(X$6-1) -> 46335 | Y7: =$D$3+7*(Y$6-1) -> 46342 | Z7: =$D$3+7*(Z$6-1) -> 46349 | AA7: =$D$3+7*(AA$6-1) -> 46356 | AB7: =$D$3+7*(AB$6-1) -> 46363 | ... AZ7: =$D$3+7*(AZ$6-1) -> 46531
B8: Project management | C8: Group
A9: PM1 | B9: Proposal review | C9: Milestone | F9: Yes | G9: 46316 | H9: 46316 | I9: 46316 | J9: 46316 | K9: =IF(C9="Task",ROUND((J9-I9+3)/7,0),"") | N9: 46316 | P9: =IF(C9="Break","",IF(C9="Milestone",IF(N9<>"","Done",IF($D$4>J9,"Overdue","Upcoming")),IF(N(O9)>=1,"Done",IF($D$4<I9,"Not started",IF($D$4>J9,"Late",IF(N(O9)+0.1<($D$4-I9+1)/(J9-I9+1),"Behind","On track")))))) -> Done | Q9: =IF(C9="Break","",ROUND((IF(N9<>"",N9,J9)-H9)/7,1)) -> 0 | R9: =IF(C9="Milestone",IF(N9<>"","✓",""),IF(AND(C9="Task",N(O9)>=1),"✓","")) -> ✓ | S9: =IF(C9="Task",K9*N(O9),"") | T9: Held 21 Oct 2026; mark 46.9%; feedback built into the v5 deck and this plan | U9: =IF($C9="Milestone",IF(AND(U$7<=$I9,U$7+6>=$I9),"◆",""),IF(AND($C9="Task",$M9<>"",U$7<=IF($N9="",$D$4,$N9),U$7+6>=$M9),"●","")) -> ◆ | V9: =IF($C9="Milestone",IF(AND(V$7<=$I9,V$7+6>=$I9),"◆",""),IF(AND($C9="Task",$M9<>"",V$7<=IF($N9="",$D$4,$N9),V$7+6>=$M9),"●","")) | W9: =IF($C9="Milestone",IF(AND(W$7<=$I9,W$7+6>=$I9),"◆",""),IF(AND($C9="Task",$M9<>"",W$7<=IF($N9="",$D$4,$N9),W$7+6>=$M9),"●","")) | X9: =IF($C9="Milestone",IF(AND(X$7<=$I9,X$7+6>=$I9),"◆",""),IF(AND($C9="Task",$M9<>"",X$7<=IF($N9="",$D$4,$N9),X$7+6>=$M9),"●","")) | Y9: =IF($C9="Milestone",IF(AND(Y$7<=$I9,Y$7+6>=$I9),"◆",""),IF(AND($C9="Task",$M9<>"",Y$7<=IF($N9="",$D$4,$N9),Y$7+6>=$M9),"●","")) | Z9: =IF($C9="Milestone",IF(AND(Z$7<=$I9,Z$7+6>=$I9),"◆",""),IF(AND($C9="Task",$M9<>"",Z$7<=IF($N9="",$D$4,$N9),Z$7+6>=$M9),"●","")) | AA9: =IF($C9="Milestone",IF(AND(AA$7<=$I9,AA$7+6>=$I9),"◆",""),IF(AND($C9="Task",$M9<>"",AA$7<=IF($N9="",$D$4,$N9),AA$7+6>=$M9),"●","")) | AB9: =IF($C9="Milestone",IF(AND(AB$7<=$I9,AB$7+6>=$I9),"◆",""),IF(AND($C9="Task",$M9<>"",AB$7<=IF($N9="",$D$4,$N9),AB$7+6>=$M9),"●","")) | ... AZ9: =IF($C9="Milestone",IF(AND(AZ$7<=$I9,AZ$7+6>=$I9),"◆",""),IF(AND($C9="Task",$M9<>"",AZ$7<=IF($N9="",$D$4,$N9),AZ$7+6>=$M9),"●",""))
A10: PM2 | B10: Confirm Blackboard tasks (ethics, H&S, codes, inclusion) signed and uploaded | C10: Task | F10: Yes | G10: 46321 | H10: 46325 | I10: 46321 | J10: 46325 | K10: =IF(C10="Task",ROUND((J10-I10+3)/7,0),"") -> 1 | L10: 0 | P10: =IF(C10="Break","",IF(C10="Milestone",IF(N10<>"","Done",IF($D$4>J10,"Overdue","Upcoming")),IF(N(O10)>=1,"Done",IF($D$4<I10,"Not started",IF($D$4>J10,"Late",IF(N(O10)+0.1<($D$4-I10+1)/(J10-I10+1),"Behind","On track")))))) -> Not started | Q10: =IF(C10="Break","",ROUND((IF(N10<>"",N10,J10)-H10)/7,1)) -> 0 | R10: =IF(C10="Milestone",IF(N10<>"","✓",""),IF(AND(C10="Task",N(O10)>=1),"✓","")) | S10: =IF(C10="Task",K10*N(O10),"") -> 0 | U10: =IF($C10="Milestone",IF(AND(U$7<=$I10,U$7+6>=$I10),"◆",""),IF(AND($C10="Task",$M10<>"",U$7<=IF($N10="",$D$4,$N10),U$7+6>=$M10),"●","")) | V10: =IF($C10="Milestone",IF(AND(V$7<=$I10,V$7+6>=$I10),"◆",""),IF(AND($C10="Task",$M10<>"",V$7<=IF($N10="",$D$4,$N10),V$7+6>=$M10),"●","")) | W10: =IF($C10="Milestone",IF(AND(W$7<=$I10,W$7+6>=$I10),"◆",""),IF(AND($C10="Task",$M10<>"",W$7<=IF($N10="",$D$4,$N10),W$7+6>=$M10),"●","")) | X10: =IF($C10="Milestone",IF(AND(X$7<=$I10,X$7+6>=$I10),"◆",""),IF(AND($C10="Task",$M10<>"",X$7<=IF($N10="",$D$4,$N10),X$7+6>=$M10),"●","")) | Y10: =IF($C10="Milestone",IF(AND(Y$7<=$I10,Y$7+6>=$I10),"◆",""),IF(AND($C10="Task",$M10<>"",Y$7<=IF($N10="",$D$4,$N10),Y$7+6>=$M10),"●","")) | Z10: =IF($C10="Milestone",IF(AND(Z$7<=$I10,Z$7+6>=$I10),"◆",""),IF(AND($C10="Task",$M10<>"",Z$7<=IF($N10="",$D$4,$N10),Z$7+6>=$M10),"●","")) | AA10: =IF($C10="Milestone",IF(AND(AA$7<=$I10,AA$7+6>=$I10),"◆",""),IF(AND($C10="Task",$M10<>"",AA$7<=IF($N10="",$D$4,$N10),AA$7+6>=$M10),"●","")) | AB10: =IF($C10="Milestone",IF(AND(AB$7<=$I10,AB$7+6>=$I10),"◆",""),IF(AND($C10="Task",$M10<>"",AB$7<=IF($N10="",$D$4,$N10),AB$7+6>=$M10),"●","")) | ... AZ10: =IF($C10="Milestone",IF(AND(AZ$7<=$I10,AZ$7+6>=$I10),"◆",""),IF(AND($C10="Task",$M10<>"",AZ$7<=IF($N10="",$D$4,$N10),AZ$7+6>=$M10),"●",""))
A11: PM3 | B11: Set up hardback logbook; first signed entry | C11: Task | F11: No | G11: 46321 | H11: 46325 | I11: 46314 | J11: 46325 | K11: =IF(C11="Task",ROUND((J11-I11+3)/7,0),"") -> 2 | L11: 0 | P11: =IF(C11="Break","",IF(C11="Milestone",IF(N11<>"","Done",IF($D$4>J11,"Overdue","Upcoming")),IF(N(O11)>=1,"Done",IF($D$4<I11,"Not started",IF($D$4>J11,"Late",IF(N(O11)+0.1<($D$4-I11+1)/(J11-I11+1),"Behind","On track")))))) -> Behind | Q11: =IF(C11="Break","",ROUND((IF(N11<>"",N11,J11)-H11)/7,1)) -> 0 | R11: =IF(C11="Milestone",IF(N11<>"","✓",""),IF(AND(C11="Task",N(O11)>=1),"✓","")) | S11: =IF(C11="Task",K11*N(O11),"") -> 0 | U11: =IF($C11="Milestone",IF(AND(U$7<=$I11,U$7+6>=$I11),"◆",""),IF(AND($C11="Task",$M11<>"",U$7<=IF($N11="",$D$4,$N11),U$7+6>=$M11),"●","")) | V11: =IF($C11="Milestone",IF(AND(V$7<=$I11,V$7+6>=$I11),"◆",""),IF(AND($C11="Task",$M11<>"",V$7<=IF($N11="",$D$4,$N11),V$7+6>=$M11),"●","")) | W11: =IF($C11="Milestone",IF(AND(W$7<=$I11,W$7+6>=$I11),"◆",""),IF(AND($C11="Task",$M11<>"",W$7<=IF($N11="",$D$4,$N11),W$7+6>=$M11),"●","")) | X11: =IF($C11="Milestone",IF(AND(X$7<=$I11,X$7+6>=$I11),"◆",""),IF(AND($C11="Task",$M11<>"",X$7<=IF($N11="",$D$4,$N11),X$7+6>=$M11),"●","")) | Y11: =IF($C11="Milestone",IF(AND(Y$7<=$I11,Y$7+6>=$I11),"◆",""),IF(AND($C11="Task",$M11<>"",Y$7<=IF($N11="",$D$4,$N11),Y$7+6>=$M11),"●","")) | Z11: =IF($C11="Milestone",IF(AND(Z$7<=$I11,Z$7+6>=$I11),"◆",""),IF(AND($C11="Task",$M11<>"",Z$7<=IF($N11="",$D$4,$N11),Z$7+6>=$M11),"●","")) | AA11: =IF($C11="Milestone",IF(AND(AA$7<=$I11,AA$7+6>=$I11),"◆",""),IF(AND($C11="Task",$M11<>"",AA$7<=IF($N11="",$D$4,$N11),AA$7+6>=$M11),"●","")) | AB11: =IF($C11="Milestone",IF(AND(AB$7<=$I11,AB$7+6>=$I11),"◆",""),IF(AND($C11="Task",$M11<>"",AB$7<=IF($N11="",$D$4,$N11),AB$7+6>=$M11),"●","")) | ... AZ11: =IF($C11="Milestone",IF(AND(AZ$7<=$I11,AZ$7+6>=$I11),"◆",""),IF(AND($C11="Task",$M11<>"",AZ$7<=IF($N11="",$D$4,$N11),AZ$7+6>=$M11),"●",""))
A12: PM4 | B12: Technical risk register v1 (review every fortnight after) | C12: Task | F12: No | G12: 46321 | H12: 46325 | I12: 46314 | J12: 46325 | K12: =IF(C12="Task",ROUND((J12-I12+3)/7,0),"") -> 2 | L12: 1 | P12: =IF(C12="Break","",IF(C12="Milestone",IF(N12<>"","Done",IF($D$4>J12,"Overdue","Upcoming")),IF(N(O12)>=1,"Done",IF($D$4<I12,"Not started",IF($D$4>J12,"Late",IF(N(O12)+0.1<($D$4-I12+1)/(J12-I12+1),"Behind","On track")))))) -> Behind | Q12: =IF(C12="Break","",ROUND((IF(N12<>"",N12,J12)-H12)/7,1)) -> 0 | R12: =IF(C12="Milestone",IF(N12<>"","✓",""),IF(AND(C12="Task",N(O12)>=1),"✓","")) | S12: =IF(C12="Task",K12*N(O12),"") -> 0 | U12: =IF($C12="Milestone",IF(AND(U$7<=$I12,U$7+6>=$I12),"◆",""),IF(AND($C12="Task",$M12<>"",U$7<=IF($N12="",$D$4,$N12),U$7+6>=$M12),"●","")) | V12: =IF($C12="Milestone",IF(AND(V$7<=$I12,V$7+6>=$I12),"◆",""),IF(AND($C12="Task",$M12<>"",V$7<=IF($N12="",$D$4,$N12),V$7+6>=$M12),"●","")) | W12: =IF($C12="Milestone",IF(AND(W$7<=$I12,W$7+6>=$I12),"◆",""),IF(AND($C12="Task",$M12<>"",W$7<=IF($N12="",$D$4,$N12),W$7+6>=$M12),"●","")) | X12: =IF($C12="Milestone",IF(AND(X$7<=$I12,X$7+6>=$I12),"◆",""),IF(AND($C12="Task",$M12<>"",X$7<=IF($N12="",$D$4,$N12),X$7+6>=$M12),"●","")) | Y12: =IF($C12="Milestone",IF(AND(Y$7<=$I12,Y$7+6>=$I12),"◆",""),IF(AND($C12="Task",$M12<>"",Y$7<=IF($N12="",$D$4,$N12),Y$7+6>=$M12),"●","")) | Z12: =IF($C12="Milestone",IF(AND(Z$7<=$I12,Z$7+6>=$I12),"◆",""),IF(AND($C12="Task",$M12<>"",Z$7<=IF($N12="",$D$4,$N12),Z$7+6>=$M12),"●","")) | AA12: =IF($C12="Milestone",IF(AND(AA$7<=$I12,AA$7+6>=$I12),"◆",""),IF(AND($C12="Task",$M12<>"",AA$7<=IF($N12="",$D$4,$N12),AA$7+6>=$M12),"●","")) | AB12: =IF($C12="Milestone",IF(AND(AB$7<=$I12,AB$7+6>=$I12),"◆",""),IF(AND($C12="Task",$M12<>"",AB$7<=IF($N12="",$D$4,$N12),AB$7+6>=$M12),"●","")) | ... AZ12: =IF($C12="Milestone",IF(AND(AZ$7<=$I12,AZ$7+6>=$I12),"◆",""),IF(AND($C12="Task",$M12<>"",AZ$7<=IF($N12="",$D$4,$N12),AZ$7+6>=$M12),"●",""))
A13: PM5 | B13: Supervisor meetings, fortnightly, with minutes (term 1) | C13: Task | F13: No | G13: 46314 | H13: 46374 | I13: 46314 | J13: 46374 | K13: =IF(C13="Task",ROUND((J13-I13+3)/7,0),"") -> 9 | L13: 0 | P13: =IF(C13="Break","",IF(C13="Milestone",IF(N13<>"","Done",IF($D$4>J13,"Overdue","Upcoming")),IF(N(O13)>=1,"Done",IF($D$4<I13,"Not started",IF($D$4>J13,"Late",IF(N(O13)+0.1<($D$4-I13+1)/(J13-I13+1),"Behind","On track")))))) -> On track | Q13: =IF(C13="Break","",ROUND((IF(N13<>"",N13,J13)-H13)/7,1)) -> 0 | R13: =IF(C13="Milestone",IF(N13<>"","✓",""),IF(AND(C13="Task",N(O13)>=1),"✓","")) | S13: =IF(C13="Task",K13*N(O13),"") -> 0 | U13: =IF($C13="Milestone",IF(AND(U$7<=$I13,U$7+6>=$I13),"◆",""),IF(AND($C13="Task",$M13<>"",U$7<=IF($N13="",$D$4,$N13),U$7+6>=$M13),"●","")) | V13: =IF($C13="Milestone",IF(AND(V$7<=$I13,V$7+6>=$I13),"◆",""),IF(AND($C13="Task",$M13<>"",V$7<=IF($N13="",$D$4,$N13),V$7+6>=$M13),"●","")) | W13: =IF($C13="Milestone",IF(AND(W$7<=$I13,W$7+6>=$I13),"◆",""),IF(AND($C13="Task",$M13<>"",W$7<=IF($N13="",$D$4,$N13),W$7+6>=$M13),"●","")) | X13: =IF($C13="Milestone",IF(AND(X$7<=$I13,X$7+6>=$I13),"◆",""),IF(AND($C13="Task",$M13<>"",X$7<=IF($N13="",$D$4,$N13),X$7+6>=$M13),"●","")) | Y13: =IF($C13="Milestone",IF(AND(Y$7<=$I13,Y$7+6>=$I13),"◆",""),IF(AND($C13="Task",$M13<>"",Y$7<=IF($N13="",$D$4,$N13),Y$7+6>=$M13),"●","")) | Z13: =IF($C13="Milestone",IF(AND(Z$7<=$I13,Z$7+6>=$I13),"◆",""),IF(AND($C13="Task",$M13<>"",Z$7<=IF($N13="",$D$4,$N13),Z$7+6>=$M13),"●","")) | AA13: =IF($C13="Milestone",IF(AND(AA$7<=$I13,AA$7+6>=$I13),"◆",""),IF(AND($C13="Task",$M13<>"",AA$7<=IF($N13="",$D$4,$N13),AA$7+6>=$M13),"●","")) | AB13: =IF($C13="Milestone",IF(AND(AB$7<=$I13,AB$7+6>=$I13),"◆",""),IF(AND($C13="Task",$M13<>"",AB$7<=IF($N13="",$D$4,$N13),AB$7+6>=$M13),"●","")) | ... AZ13: =IF($C13="Milestone",IF(AND(AZ$7<=$I13,AZ$7+6>=$I13),"◆",""),IF(AND($C13="Task",$M13<>"",AZ$7<=IF($N13="",$D$4,$N13),AZ$7+6>=$M13),"●",""))
A14: PM6 | B14: Supervisor meetings, weekly, with minutes (term 2) | C14: Task | F14: No | G14: 46412 | H14: 46500 | I14: 46412 | J14: 46500 | K14: =IF(C14="Task",ROUND((J14-I14+3)/7,0),"") -> 13 | L14: 0 | P14: =IF(C14="Break","",IF(C14="Milestone",IF(N14<>"","Done",IF($D$4>J14,"Overdue","Upcoming")),IF(N(O14)>=1,"Done",IF($D$4<I14,"Not started",IF($D$4>J14,"Late",IF(N(O14)+0.1<($D$4-I14+1)/(J14-I14+1),"Behind","On track")))))) -> Not started | Q14: =IF(C14="Break","",ROUND((IF(N14<>"",N14,J14)-H14)/7,1)) -> 0 | R14: =IF(C14="Milestone",IF(N14<>"","✓",""),IF(AND(C14="Task",N(O14)>=1),"✓","")) | S14: =IF(C14="Task",K14*N(O14),"") -> 0 | U14: =IF($C14="Milestone",IF(AND(U$7<=$I14,U$7+6>=$I14),"◆",""),IF(AND($C14="Task",$M14<>"",U$7<=IF($N14="",$D$4,$N14),U$7+6>=$M14),"●","")) | V14: =IF($C14="Milestone",IF(AND(V$7<=$I14,V$7+6>=$I14),"◆",""),IF(AND($C14="Task",$M14<>"",V$7<=IF($N14="",$D$4,$N14),V$7+6>=$M14),"●","")) | W14: =IF($C14="Milestone",IF(AND(W$7<=$I14,W$7+6>=$I14),"◆",""),IF(AND($C14="Task",$M14<>"",W$7<=IF($N14="",$D$4,$N14),W$7+6>=$M14),"●","")) | X14: =IF($C14="Milestone",IF(AND(X$7<=$I14,X$7+6>=$I14),"◆",""),IF(AND($C14="Task",$M14<>"",X$7<=IF($N14="",$D$4,$N14),X$7+6>=$M14),"●","")) | Y14: =IF($C14="Milestone",IF(AND(Y$7<=$I14,Y$7+6>=$I14),"◆",""),IF(AND($C14="Task",$M14<>"",Y$7<=IF($N14="",$D$4,$N14),Y$7+6>=$M14),"●","")) | Z14: =IF($C14="Milestone",IF(AND(Z$7<=$I14,Z$7+6>=$I14),"◆",""),IF(AND($C14="Task",$M14<>"",Z$7<=IF($N14="",$D$4,$N14),Z$7+6>=$M14),"●","")) | AA14: =IF($C14="Milestone",IF(AND(AA$7<=$I14,AA$7+6>=$I14),"◆",""),IF(AND($C14="Task",$M14<>"",AA$7<=IF($N14="",$D$4,$N14),AA$7+6>=$M14),"●","")) | AB14: =IF($C14="Milestone",IF(AND(AB$7<=$I14,AB$7+6>=$I14),"◆",""),IF(AND($C14="Task",$M14<>"",AB$7<=IF($N14="",$D$4,$N14),AB$7+6>=$M14),"●","")) | ... AZ14: =IF($C14="Milestone",IF(AND(AZ$7<=$I14,AZ$7+6>=$I14),"◆",""),IF(AND($C14="Task",$M14<>"",AZ$7<=IF($N14="",$D$4,$N14),AZ$7+6>=$M14),"●",""))
A15: PM7 | B15: Mid-term pack: deck, logbook, literature review, original and revised Gantt | C15: Task | E15: F3 | F15: Yes | G15: 46433 | H15: 46437 | I15: 46426 | J15: 46437 | K15: =IF(C15="Task",ROUND((J15-I15+3)/7,0),"") -> 2 | L15: 0 | P15: =IF(C15="Break","",IF(C15="Milestone",IF(N15<>"","Done",IF($D$4>J15,"Overdue","Upcoming")),IF(N(O15)>=1,"Done",IF($D$4<I15,"Not started",IF($D$4>J15,"Late",IF(N(O15)+0.1<($D$4-I15+1)/(J15-I15+1),"Behind","On track")))))) -> Not started | Q15: =IF(C15="Break","",ROUND((IF(N15<>"",N15,J15)-H15)/7,1)) -> 0 | R15: =IF(C15="Milestone",IF(N15<>"","✓",""),IF(AND(C15="Task",N(O15)>=1),"✓","")) | S15: =IF(C15="Task",K15*N(O15),"") -> 0 | U15: =IF($C15="Milestone",IF(AND(U$7<=$I15,U$7+6>=$I15),"◆",""),IF(AND($C15="Task",$M15<>"",U$7<=IF($N15="",$D$4,$N15),U$7+6>=$M15),"●","")) | V15: =IF($C15="Milestone",IF(AND(V$7<=$I15,V$7+6>=$I15),"◆",""),IF(AND($C15="Task",$M15<>"",V$7<=IF($N15="",$D$4,$N15),V$7+6>=$M15),"●","")) | W15: =IF($C15="Milestone",IF(AND(W$7<=$I15,W$7+6>=$I15),"◆",""),IF(AND($C15="Task",$M15<>"",W$7<=IF($N15="",$D$4,$N15),W$7+6>=$M15),"●","")) | X15: =IF($C15="Milestone",IF(AND(X$7<=$I15,X$7+6>=$I15),"◆",""),IF(AND($C15="Task",$M15<>"",X$7<=IF($N15="",$D$4,$N15),X$7+6>=$M15),"●","")) | Y15: =IF($C15="Milestone",IF(AND(Y$7<=$I15,Y$7+6>=$I15),"◆",""),IF(AND($C15="Task",$M15<>"",Y$7<=IF($N15="",$D$4,$N15),Y$7+6>=$M15),"●","")) | Z15: =IF($C15="Milestone",IF(AND(Z$7<=$I15,Z$7+6>=$I15),"◆",""),IF(AND($C15="Task",$M15<>"",Z$7<=IF($N15="",$D$4,$N15),Z$7+6>=$M15),"●","")) | AA15: =IF($C15="Milestone",IF(AND(AA$7<=$I15,AA$7+6>=$I15),"◆",""),IF(AND($C15="Task",$M15<>"",AA$7<=IF($N15="",$D$4,$N15),AA$7+6>=$M15),"●","")) | AB15: =IF($C15="Milestone",IF(AND(AB$7<=$I15,AB$7+6>=$I15),"◆",""),IF(AND($C15="Task",$M15<>"",AB$7<=IF($N15="",$D$4,$N15),AB$7+6>=$M15),"●","")) | ... AZ15: =IF($C15="Milestone",IF(AND(AZ$7<=$I15,AZ$7+6>=$I15),"◆",""),IF(AND($C15="Task",$M15<>"",AZ$7<=IF($N15="",$D$4,$N15),AZ$7+6>=$M15),"●",""))
A16: PM8 | B16: Mid-term review (confirm date on Blackboard) | C16: Milestone | E16: PM7 | F16: Yes | G16: 46440 | H16: 46440 | I16: 46440 | J16: 46440 | K16: =IF(C16="Task",ROUND((J16-I16+3)/7,0),"") | P16: =IF(C16="Break","",IF(C16="Milestone",IF(N16<>"","Done",IF($D$4>J16,"Overdue","Upcoming")),IF(N(O16)>=1,"Done",IF($D$4<I16,"Not started",IF($D$4>J16,"Late",IF(N(O16)+0.1<($D$4-I16+1)/(J16-I16+1),"Behind","On track")))))) -> Upcoming | Q16: =IF(C16="Break","",ROUND((IF(N16<>"",N16,J16)-H16)/7,1)) -> 0 | R16: =IF(C16="Milestone",IF(N16<>"","✓",""),IF(AND(C16="Task",N(O16)>=1),"✓","")) | S16: =IF(C16="Task",K16*N(O16),"") | U16: =IF($C16="Milestone",IF(AND(U$7<=$I16,U$7+6>=$I16),"◆",""),IF(AND($C16="Task",$M16<>"",U$7<=IF($N16="",$D$4,$N16),U$7+6>=$M16),"●","")) | V16: =IF($C16="Milestone",IF(AND(V$7<=$I16,V$7+6>=$I16),"◆",""),IF(AND($C16="Task",$M16<>"",V$7<=IF($N16="",$D$4,$N16),V$7+6>=$M16),"●","")) | W16: =IF($C16="Milestone",IF(AND(W$7<=$I16,W$7+6>=$I16),"◆",""),IF(AND($C16="Task",$M16<>"",W$7<=IF($N16="",$D$4,$N16),W$7+6>=$M16),"●","")) | X16: =IF($C16="Milestone",IF(AND(X$7<=$I16,X$7+6>=$I16),"◆",""),IF(AND($C16="Task",$M16<>"",X$7<=IF($N16="",$D$4,$N16),X$7+6>=$M16),"●","")) | Y16: =IF($C16="Milestone",IF(AND(Y$7<=$I16,Y$7+6>=$I16),"◆",""),IF(AND($C16="Task",$M16<>"",Y$7<=IF($N16="",$D$4,$N16),Y$7+6>=$M16),"●","")) | Z16: =IF($C16="Milestone",IF(AND(Z$7<=$I16,Z$7+6>=$I16),"◆",""),IF(AND($C16="Task",$M16<>"",Z$7<=IF($N16="",$D$4,$N16),Z$7+6>=$M16),"●","")) | AA16: =IF($C16="Milestone",IF(AND(AA$7<=$I16,AA$7+6>=$I16),"◆",""),IF(AND($C16="Task",$M16<>"",AA$7<=IF($N16="",$D$4,$N16),AA$7+6>=$M16),"●","")) | AB16: =IF($C16="Milestone",IF(AND(AB$7<=$I16,AB$7+6>=$I16),"◆",""),IF(AND($C16="Task",$M16<>"",AB$7<=IF($N16="",$D$4,$N16),AB$7+6>=$M16),"●","")) | ... AZ16: =IF($C16="Milestone",IF(AND(AZ$7<=$I16,AZ$7+6>=$I16),"◆",""),IF(AND($C16="Task",$M16<>"",AZ$7<=IF($N16="",$D$4,$N16),AZ$7+6>=$M16),"●",""))
B17: Literature review | C17: Group
A18: L1 | B18: Literature search: 15 sources logged | C18: Task | F18: No | G18: 46314 | H18: 46332 | I18: 46314 | J18: 46325 | K18: =IF(C18="Task",ROUND((J18-I18+3)/7,0),"") -> 2 | L18: 2 | P18: =IF(C18="Break","",IF(C18="Milestone",IF(N18<>"","Done",IF($D$4>J18,"Overdue","Upcoming")),IF(N(O18)>=1,"Done",IF($D$4<I18,"Not started",IF($D$4>J18,"Late",IF(N(O18)+0.1<($D$4-I18+1)/(J18-I18+1),"Behind","On track")))))) -> Behind | Q18: =IF(C18="Break","",ROUND((IF(N18<>"",N18,J18)-H18)/7,1)) -> -1 | R18: =IF(C18="Milestone",IF(N18<>"","✓",""),IF(AND(C18="Task",N(O18)>=1),"✓","")) | S18: =IF(C18="Task",K18*N(O18),"") -> 0 | U18: =IF($C18="Milestone",IF(AND(U$7<=$I18,U$7+6>=$I18),"◆",""),IF(AND($C18="Task",$M18<>"",U$7<=IF($N18="",$D$4,$N18),U$7+6>=$M18),"●","")) | V18: =IF($C18="Milestone",IF(AND(V$7<=$I18,V$7+6>=$I18),"◆",""),IF(AND($C18="Task",$M18<>"",V$7<=IF($N18="",$D$4,$N18),V$7+6>=$M18),"●","")) | W18: =IF($C18="Milestone",IF(AND(W$7<=$I18,W$7+6>=$I18),"◆",""),IF(AND($C18="Task",$M18<>"",W$7<=IF($N18="",$D$4,$N18),W$7+6>=$M18),"●","")) | X18: =IF($C18="Milestone",IF(AND(X$7<=$I18,X$7+6>=$I18),"◆",""),IF(AND($C18="Task",$M18<>"",X$7<=IF($N18="",$D$4,$N18),X$7+6>=$M18),"●","")) | Y18: =IF($C18="Milestone",IF(AND(Y$7<=$I18,Y$7+6>=$I18),"◆",""),IF(AND($C18="Task",$M18<>"",Y$7<=IF($N18="",$D$4,$N18),Y$7+6>=$M18),"●","")) | Z18: =IF($C18="Milestone",IF(AND(Z$7<=$I18,Z$7+6>=$I18),"◆",""),IF(AND($C18="Task",$M18<>"",Z$7<=IF($N18="",$D$4,$N18),Z$7+6>=$M18),"●","")) | AA18: =IF($C18="Milestone",IF(AND(AA$7<=$I18,AA$7+6>=$I18),"◆",""),IF(AND($C18="Task",$M18<>"",AA$7<=IF($N18="",$D$4,$N18),AA$7+6>=$M18),"●","")) | AB18: =IF($C18="Milestone",IF(AND(AB$7<=$I18,AB$7+6>=$I18),"◆",""),IF(AND($C18="Task",$M18<>"",AB$7<=IF($N18="",$D$4,$N18),AB$7+6>=$M18),"●","")) | ... AZ18: =IF($C18="Milestone",IF(AND(AZ$7<=$I18,AZ$7+6>=$I18),"◆",""),IF(AND($C18="Task",$M18<>"",AZ$7<=IF($N18="",$D$4,$N18),AZ$7+6>=$M18),"●",""))
A19: L2 | B19: Literature comparison table and gap (30 sources) | C19: Task | E19: L1 | F19: No | G19: 46335 | H19: 46353 | I19: 46328 | J19: 46339 | K19: =IF(C19="Task",ROUND((J19-I19+3)/7,0),"") -> 2 | L19: 2 | P19: =IF(C19="Break","",IF(C19="Milestone",IF(N19<>"","Done",IF($D$4>J19,"Overdue","Upcoming")),IF(N(O19)>=1,"Done",IF($D$4<I19,"Not started",IF($D$4>J19,"Late",IF(N(O19)+0.1<($D$4-I19+1)/(J19-I19+1),"Behind","On track")))))) -> Not started | Q19: =IF(C19="Break","",ROUND((IF(N19<>"",N19,J19)-H19)/7,1)) -> -2 | R19: =IF(C19="Milestone",IF(N19<>"","✓",""),IF(AND(C19="Task",N(O19)>=1),"✓","")) | S19: =IF(C19="Task",K19*N(O19),"") -> 0 | U19: =IF($C19="Milestone",IF(AND(U$7<=$I19,U$7+6>=$I19),"◆",""),IF(AND($C19="Task",$M19<>"",U$7<=IF($N19="",$D$4,$N19),U$7+6>=$M19),"●","")) | V19: =IF($C19="Milestone",IF(AND(V$7<=$I19,V$7+6>=$I19),"◆",""),IF(AND($C19="Task",$M19<>"",V$7<=IF($N19="",$D$4,$N19),V$7+6>=$M19),"●","")) | W19: =IF($C19="Milestone",IF(AND(W$7<=$I19,W$7+6>=$I19),"◆",""),IF(AND($C19="Task",$M19<>"",W$7<=IF($N19="",$D$4,$N19),W$7+6>=$M19),"●","")) | X19: =IF($C19="Milestone",IF(AND(X$7<=$I19,X$7+6>=$I19),"◆",""),IF(AND($C19="Task",$M19<>"",X$7<=IF($N19="",$D$4,$N19),X$7+6>=$M19),"●","")) | Y19: =IF($C19="Milestone",IF(AND(Y$7<=$I19,Y$7+6>=$I19),"◆",""),IF(AND($C19="Task",$M19<>"",Y$7<=IF($N19="",$D$4,$N19),Y$7+6>=$M19),"●","")) | Z19: =IF($C19="Milestone",IF(AND(Z$7<=$I19,Z$7+6>=$I19),"◆",""),IF(AND($C19="Task",$M19<>"",Z$7<=IF($N19="",$D$4,$N19),Z$7+6>=$M19),"●","")) | AA19: =IF($C19="Milestone",IF(AND(AA$7<=$I19,AA$7+6>=$I19),"◆",""),IF(AND($C19="Task",$M19<>"",AA$7<=IF($N19="",$D$4,$N19),AA$7+6>=$M19),"●","")) | AB19: =IF($C19="Milestone",IF(AND(AB$7<=$I19,AB$7+6>=$I19),"◆",""),IF(AND($C19="Task",$M19<>"",AB$7<=IF($N19="",$D$4,$N19),AB$7+6>=$M19),"●","")) | ... AZ19: =IF($C19="Milestone",IF(AND(AZ$7<=$I19,AZ$7+6>=$I19),"◆",""),IF(AND($C19="Task",$M19<>"",AZ$7<=IF($N19="",$D$4,$N19),AZ$7+6>=$M19),"●",""))
A20: L3 | B20: Literature review chapter drafted | C20: Task | E20: L2 | F20: No | G20: 46356 | H20: 46374 | I20: 46342 | J20: 46353 | K20: =IF(C20="Task",ROUND((J20-I20+3)/7,0),"") -> 2 | L20: 0 | P20: =IF(C20="Break","",IF(C20="Milestone",IF(N20<>"","Done",IF($D$4>J20,"Overdue","Upcoming")),IF(N(O20)>=1,"Done",IF($D$4<I20,"Not started",IF($D$4>J20,"Late",IF(N(O20)+0.1<($D$4-I20+1)/(J20-I20+1),"Behind","On track")))))) -> Not started | Q20: =IF(C20="Break","",ROUND((IF(N20<>"",N20,J20)-H20)/7,1)) -> -3 | R20: =IF(C20="Milestone",IF(N20<>"","✓",""),IF(AND(C20="Task",N(O20)>=1),"✓","")) | S20: =IF(C20="Task",K20*N(O20),"") -> 0 | U20: =IF($C20="Milestone",IF(AND(U$7<=$I20,U$7+6>=$I20),"◆",""),IF(AND($C20="Task",$M20<>"",U$7<=IF($N20="",$D$4,$N20),U$7+6>=$M20),"●","")) | V20: =IF($C20="Milestone",IF(AND(V$7<=$I20,V$7+6>=$I20),"◆",""),IF(AND($C20="Task",$M20<>"",V$7<=IF($N20="",$D$4,$N20),V$7+6>=$M20),"●","")) | W20: =IF($C20="Milestone",IF(AND(W$7<=$I20,W$7+6>=$I20),"◆",""),IF(AND($C20="Task",$M20<>"",W$7<=IF($N20="",$D$4,$N20),W$7+6>=$M20),"●","")) | X20: =IF($C20="Milestone",IF(AND(X$7<=$I20,X$7+6>=$I20),"◆",""),IF(AND($C20="Task",$M20<>"",X$7<=IF($N20="",$D$4,$N20),X$7+6>=$M20),"●","")) | Y20: =IF($C20="Milestone",IF(AND(Y$7<=$I20,Y$7+6>=$I20),"◆",""),IF(AND($C20="Task",$M20<>"",Y$7<=IF($N20="",$D$4,$N20),Y$7+6>=$M20),"●","")) | Z20: =IF($C20="Milestone",IF(AND(Z$7<=$I20,Z$7+6>=$I20),"◆",""),IF(AND($C20="Task",$M20<>"",Z$7<=IF($N20="",$D$4,$N20),Z$7+6>=$M20),"●","")) | AA20: =IF($C20="Milestone",IF(AND(AA$7<=$I20,AA$7+6>=$I20),"◆",""),IF(AND($C20="Task",$M20<>"",AA$7<=IF($N20="",$D$4,$N20),AA$7+6>=$M20),"●","")) | AB20: =IF($C20="Milestone",IF(AND(AB$7<=$I20,AB$7+6>=$I20),"◆",""),IF(AND($C20="Task",$M20<>"",AB$7<=IF($N20="",$D$4,$N20),AB$7+6>=$M20),"●","")) | ... AZ20: =IF($C20="Milestone",IF(AND(AZ$7<=$I20,AZ$7+6>=$I20),"◆",""),IF(AND($C20="Task",$M20<>"",AZ$7<=IF($N20="",$D$4,$N20),AZ$7+6>=$M20),"●",""))
A21: L4 | B21: Literature review draft sent to Dr Shah | C21: Milestone | E21: L3 | F21: No | G21: 46374 | H21: 46374 | I21: 46353 | J21: 46353 | K21: =IF(C21="Task",ROUND((J21-I21+3)/7,0),"") | P21: =IF(C21="Break","",IF(C21="Milestone",IF(N21<>"","Done",IF($D$4>J21,"Overdue","Upcoming")),IF(N(O21)>=1,"Done",IF($D$4<I21,"Not started",IF($D$4>J21,"Late",IF(N(O21)+0.1<($D$4-I21+1)/(J21-I21+1),"Behind","On track")))))) -> Upcoming | Q21: =IF(C21="Break","",ROUND((IF(N21<>"",N21,J21)-H21)/7,1)) -> -3 | R21: =IF(C21="Milestone",IF(N21<>"","✓",""),IF(AND(C21="Task",N(O21)>=1),"✓","")) | S21: =IF(C21="Task",K21*N(O21),"") | U21: =IF($C21="Milestone",IF(AND(U$7<=$I21,U$7+6>=$I21),"◆",""),IF(AND($C21="Task",$M21<>"",U$7<=IF($N21="",$D$4,$N21),U$7+6>=$M21),"●","")) | V21: =IF($C21="Milestone",IF(AND(V$7<=$I21,V$7+6>=$I21),"◆",""),IF(AND($C21="Task",$M21<>"",V$7<=IF($N21="",$D$4,$N21),V$7+6>=$M21),"●","")) | W21: =IF($C21="Milestone",IF(AND(W$7<=$I21,W$7+6>=$I21),"◆",""),IF(AND($C21="Task",$M21<>"",W$7<=IF($N21="",$D$4,$N21),W$7+6>=$M21),"●","")) | X21: =IF($C21="Milestone",IF(AND(X$7<=$I21,X$7+6>=$I21),"◆",""),IF(AND($C21="Task",$M21<>"",X$7<=IF($N21="",$D$4,$N21),X$7+6>=$M21),"●","")) | Y21: =IF($C21="Milestone",IF(AND(Y$7<=$I21,Y$7+6>=$I21),"◆",""),IF(AND($C21="Task",$M21<>"",Y$7<=IF($N21="",$D$4,$N21),Y$7+6>=$M21),"●","")) | Z21: =IF($C21="Milestone",IF(AND(Z$7<=$I21,Z$7+6>=$I21),"◆",""),IF(AND($C21="Task",$M21<>"",Z$7<=IF($N21="",$D$4,$N21),Z$7+6>=$M21),"●","")) -> ◆ | AA21: =IF($C21="Milestone",IF(AND(AA$7<=$I21,AA$7+6>=$I21),"◆",""),IF(AND($C21="Task",$M21<>"",AA$7<=IF($N21="",$D$4,$N21),AA$7+6>=$M21),"●","")) | AB21: =IF($C21="Milestone",IF(AND(AB$7<=$I21,AB$7+6>=$I21),"◆",""),IF(AND($C21="Task",$M21<>"",AB$7<=IF($N21="",$D$4,$N21),AB$7+6>=$M21),"●","")) | ... AZ21: =IF($C21="Milestone",IF(AND(AZ$7<=$I21,AZ$7+6>=$I21),"◆",""),IF(AND($C21="Task",$M21<>"",AZ$7<=IF($N21="",$D$4,$N21),AZ$7+6>=$M21),"●",""))
B22: Data and software (laptop) | C22: Group
A23: S1 | B23: Download and store a year of Octopus and Elexon data | C23: Task | D23: O1 | F23: No | G23: 46321 | H23: 46325 | I23: 46314 | J23: 46325 | K23: =IF(C23="Task",ROUND((J23-I23+3)/7,0),"") -> 2 | L23: 1 | P23: =IF(C23="Break","",IF(C23="Milestone",IF(N23<>"","Done",IF($D$4>J23,"Overdue","Upcoming")),IF(N(O23)>=1,"Done",IF($D$4<I23,"Not started",IF($D$4>J23,"Late",IF(N(O23)+0.1<($D$4-I23+1)/(J23-I23+1),"Behind","On track")))))) -> Behind | Q23: =IF(C23="Break","",ROUND((IF(N23<>"",N23,J23)-H23)/7,1)) -> 0 | R23: =IF(C23="Milestone",IF(N23<>"","✓",""),IF(AND(C23="Task",N(O23)>=1),"✓","")) | S23: =IF(C23="Task",K23*N(O23),"") -> 0 | U23: =IF($C23="Milestone",IF(AND(U$7<=$I23,U$7+6>=$I23),"◆",""),IF(AND($C23="Task",$M23<>"",U$7<=IF($N23="",$D$4,$N23),U$7+6>=$M23),"●","")) | V23: =IF($C23="Milestone",IF(AND(V$7<=$I23,V$7+6>=$I23),"◆",""),IF(AND($C23="Task",$M23<>"",V$7<=IF($N23="",$D$4,$N23),V$7+6>=$M23),"●","")) | W23: =IF($C23="Milestone",IF(AND(W$7<=$I23,W$7+6>=$I23),"◆",""),IF(AND($C23="Task",$M23<>"",W$7<=IF($N23="",$D$4,$N23),W$7+6>=$M23),"●","")) | X23: =IF($C23="Milestone",IF(AND(X$7<=$I23,X$7+6>=$I23),"◆",""),IF(AND($C23="Task",$M23<>"",X$7<=IF($N23="",$D$4,$N23),X$7+6>=$M23),"●","")) | Y23: =IF($C23="Milestone",IF(AND(Y$7<=$I23,Y$7+6>=$I23),"◆",""),IF(AND($C23="Task",$M23<>"",Y$7<=IF($N23="",$D$4,$N23),Y$7+6>=$M23),"●","")) | Z23: =IF($C23="Milestone",IF(AND(Z$7<=$I23,Z$7+6>=$I23),"◆",""),IF(AND($C23="Task",$M23<>"",Z$7<=IF($N23="",$D$4,$N23),Z$7+6>=$M23),"●","")) | AA23: =IF($C23="Milestone",IF(AND(AA$7<=$I23,AA$7+6>=$I23),"◆",""),IF(AND($C23="Task",$M23<>"",AA$7<=IF($N23="",$D$4,$N23),AA$7+6>=$M23),"●","")) | AB23: =IF($C23="Milestone",IF(AND(AB$7<=$I23,AB$7+6>=$I23),"◆",""),IF(AND($C23="Task",$M23<>"",AB$7<=IF($N23="",$D$4,$N23),AB$7+6>=$M23),"●","")) | ... AZ23: =IF($C23="Milestone",IF(AND(AZ$7<=$I23,AZ$7+6>=$I23),"◆",""),IF(AND($C23="Task",$M23<>"",AZ$7<=IF($N23="",$D$4,$N23),AZ$7+6>=$M23),"●",""))
A24: S2 | B24: Data pipeline: cleaning and alignment | C24: Task | D24: O1 | E24: S1 | F24: No | G24: 46328 | H24: 46346 | I24: 46321 | J24: 46332 | K24: =IF(C24="Task",ROUND((J24-I24+3)/7,0),"") -> 2 | L24: 1 | P24: =IF(C24="Break","",IF(C24="Milestone",IF(N24<>"","Done",IF($D$4>J24,"Overdue","Upcoming")),IF(N(O24)>=1,"Done",IF($D$4<I24,"Not started",IF($D$4>J24,"Late",IF(N(O24)+0.1<($D$4-I24+1)/(J24-I24+1),"Behind","On track")))))) -> Not started | Q24: =IF(C24="Break","",ROUND((IF(N24<>"",N24,J24)-H24)/7,1)) -> -2 | R24: =IF(C24="Milestone",IF(N24<>"","✓",""),IF(AND(C24="Task",N(O24)>=1),"✓","")) | S24: =IF(C24="Task",K24*N(O24),"") -> 0 | U24: =IF($C24="Milestone",IF(AND(U$7<=$I24,U$7+6>=$I24),"◆",""),IF(AND($C24="Task",$M24<>"",U$7<=IF($N24="",$D$4,$N24),U$7+6>=$M24),"●","")) | V24: =IF($C24="Milestone",IF(AND(V$7<=$I24,V$7+6>=$I24),"◆",""),IF(AND($C24="Task",$M24<>"",V$7<=IF($N24="",$D$4,$N24),V$7+6>=$M24),"●","")) | W24: =IF($C24="Milestone",IF(AND(W$7<=$I24,W$7+6>=$I24),"◆",""),IF(AND($C24="Task",$M24<>"",W$7<=IF($N24="",$D$4,$N24),W$7+6>=$M24),"●","")) | X24: =IF($C24="Milestone",IF(AND(X$7<=$I24,X$7+6>=$I24),"◆",""),IF(AND($C24="Task",$M24<>"",X$7<=IF($N24="",$D$4,$N24),X$7+6>=$M24),"●","")) | Y24: =IF($C24="Milestone",IF(AND(Y$7<=$I24,Y$7+6>=$I24),"◆",""),IF(AND($C24="Task",$M24<>"",Y$7<=IF($N24="",$D$4,$N24),Y$7+6>=$M24),"●","")) | Z24: =IF($C24="Milestone",IF(AND(Z$7<=$I24,Z$7+6>=$I24),"◆",""),IF(AND($C24="Task",$M24<>"",Z$7<=IF($N24="",$D$4,$N24),Z$7+6>=$M24),"●","")) | AA24: =IF($C24="Milestone",IF(AND(AA$7<=$I24,AA$7+6>=$I24),"◆",""),IF(AND($C24="Task",$M24<>"",AA$7<=IF($N24="",$D$4,$N24),AA$7+6>=$M24),"●","")) | AB24: =IF($C24="Milestone",IF(AND(AB$7<=$I24,AB$7+6>=$I24),"◆",""),IF(AND($C24="Task",$M24<>"",AB$7<=IF($N24="",$D$4,$N24),AB$7+6>=$M24),"●","")) | ... AZ24: =IF($C24="Milestone",IF(AND(AZ$7<=$I24,AZ$7+6>=$I24),"◆",""),IF(AND($C24="Task",$M24<>"",AZ$7<=IF($N24="",$D$4,$N24),AZ$7+6>=$M24),"●",""))
A25: S3 | B25: O1 met: T1 data-quality report | C25: Milestone | D25: O1 | E25: S2 | F25: No | G25: 46346 | H25: 46346 | I25: 46332 | J25: 46332 | K25: =IF(C25="Task",ROUND((J25-I25+3)/7,0),"") | P25: =IF(C25="Break","",IF(C25="Milestone",IF(N25<>"","Done",IF($D$4>J25,"Overdue","Upcoming")),IF(N(O25)>=1,"Done",IF($D$4<I25,"Not started",IF($D$4>J25,"Late",IF(N(O25)+0.1<($D$4-I25+1)/(J25-I25+1),"Behind","On track")))))) -> Upcoming | Q25: =IF(C25="Break","",ROUND((IF(N25<>"",N25,J25)-H25)/7,1)) -> -2 | R25: =IF(C25="Milestone",IF(N25<>"","✓",""),IF(AND(C25="Task",N(O25)>=1),"✓","")) | S25: =IF(C25="Task",K25*N(O25),"") | U25: =IF($C25="Milestone",IF(AND(U$7<=$I25,U$7+6>=$I25),"◆",""),IF(AND($C25="Task",$M25<>"",U$7<=IF($N25="",$D$4,$N25),U$7+6>=$M25),"●","")) | V25: =IF($C25="Milestone",IF(AND(V$7<=$I25,V$7+6>=$I25),"◆",""),IF(AND($C25="Task",$M25<>"",V$7<=IF($N25="",$D$4,$N25),V$7+6>=$M25),"●","")) | W25: =IF($C25="Milestone",IF(AND(W$7<=$I25,W$7+6>=$I25),"◆",""),IF(AND($C25="Task",$M25<>"",W$7<=IF($N25="",$D$4,$N25),W$7+6>=$M25),"●","")) -> ◆ | X25: =IF($C25="Milestone",IF(AND(X$7<=$I25,X$7+6>=$I25),"◆",""),IF(AND($C25="Task",$M25<>"",X$7<=IF($N25="",$D$4,$N25),X$7+6>=$M25),"●","")) | Y25: =IF($C25="Milestone",IF(AND(Y$7<=$I25,Y$7+6>=$I25),"◆",""),IF(AND($C25="Task",$M25<>"",Y$7<=IF($N25="",$D$4,$N25),Y$7+6>=$M25),"●","")) | Z25: =IF($C25="Milestone",IF(AND(Z$7<=$I25,Z$7+6>=$I25),"◆",""),IF(AND($C25="Task",$M25<>"",Z$7<=IF($N25="",$D$4,$N25),Z$7+6>=$M25),"●","")) | AA25: =IF($C25="Milestone",IF(AND(AA$7<=$I25,AA$7+6>=$I25),"◆",""),IF(AND($C25="Task",$M25<>"",AA$7<=IF($N25="",$D$4,$N25),AA$7+6>=$M25),"●","")) | AB25: =IF($C25="Milestone",IF(AND(AB$7<=$I25,AB$7+6>=$I25),"◆",""),IF(AND($C25="Task",$M25<>"",AB$7<=IF($N25="",$D$4,$N25),AB$7+6>=$M25),"●","")) | ... AZ25: =IF($C25="Milestone",IF(AND(AZ$7<=$I25,AZ$7+6>=$I25),"◆",""),IF(AND($C25="Task",$M25<>"",AZ$7<=IF($N25="",$D$4,$N25),AZ$7+6>=$M25),"●",""))
A26: S4 | B26: Python simulator skeleton | C26: Task | D26: O8 | E26: S2 | F26: No | G26: 46349 | H26: 46353 | I26: 46328 | J26: 46332 | K26: =IF(C26="Task",ROUND((J26-I26+3)/7,0),"") -> 1 | L26: 2 | P26: =IF(C26="Break","",IF(C26="Milestone",IF(N26<>"","Done",IF($D$4>J26,"Overdue","Upcoming")),IF(N(O26)>=1,"Done",IF($D$4<I26,"Not started",IF($D$4>J26,"Late",IF(N(O26)+0.1<($D$4-I26+1)/(J26-I26+1),"Behind","On track")))))) -> Not started | Q26: =IF(C26="Break","",ROUND((IF(N26<>"",N26,J26)-H26)/7,1)) -> -3 | R26: =IF(C26="Milestone",IF(N26<>"","✓",""),IF(AND(C26="Task",N(O26)>=1),"✓","")) | S26: =IF(C26="Task",K26*N(O26),"") -> 0 | U26: =IF($C26="Milestone",IF(AND(U$7<=$I26,U$7+6>=$I26),"◆",""),IF(AND($C26="Task",$M26<>"",U$7<=IF($N26="",$D$4,$N26),U$7+6>=$M26),"●","")) | V26: =IF($C26="Milestone",IF(AND(V$7<=$I26,V$7+6>=$I26),"◆",""),IF(AND($C26="Task",$M26<>"",V$7<=IF($N26="",$D$4,$N26),V$7+6>=$M26),"●","")) | W26: =IF($C26="Milestone",IF(AND(W$7<=$I26,W$7+6>=$I26),"◆",""),IF(AND($C26="Task",$M26<>"",W$7<=IF($N26="",$D$4,$N26),W$7+6>=$M26),"●","")) | X26: =IF($C26="Milestone",IF(AND(X$7<=$I26,X$7+6>=$I26),"◆",""),IF(AND($C26="Task",$M26<>"",X$7<=IF($N26="",$D$4,$N26),X$7+6>=$M26),"●","")) | Y26: =IF($C26="Milestone",IF(AND(Y$7<=$I26,Y$7+6>=$I26),"◆",""),IF(AND($C26="Task",$M26<>"",Y$7<=IF($N26="",$D$4,$N26),Y$7+6>=$M26),"●","")) | Z26: =IF($C26="Milestone",IF(AND(Z$7<=$I26,Z$7+6>=$I26),"◆",""),IF(AND($C26="Task",$M26<>"",Z$7<=IF($N26="",$D$4,$N26),Z$7+6>=$M26),"●","")) | AA26: =IF($C26="Milestone",IF(AND(AA$7<=$I26,AA$7+6>=$I26),"◆",""),IF(AND($C26="Task",$M26<>"",AA$7<=IF($N26="",$D$4,$N26),AA$7+6>=$M26),"●","")) | AB26: =IF($C26="Milestone",IF(AND(AB$7<=$I26,AB$7+6>=$I26),"◆",""),IF(AND($C26="Task",$M26<>"",AB$7<=IF($N26="",$D$4,$N26),AB$7+6>=$M26),"●","")) | ... AZ26: =IF($C26="Milestone",IF(AND(AZ$7<=$I26,AZ$7+6>=$I26),"◆",""),IF(AND($C26="Task",$M26<>"",AZ$7<=IF($N26="",$D$4,$N26),AZ$7+6>=$M26),"●",""))
A27: S5 | B27: Perfect plan by linear programming | C27: Task | D27: O8 | E27: S4 | F27: No | G27: 46356 | H27: 46360 | I27: 46335 | J27: 46339 | K27: =IF(C27="Task",ROUND((J27-I27+3)/7,0),"") -> 1 | L27: 2 | P27: =IF(C27="Break","",IF(C27="Milestone",IF(N27<>"","Done",IF($D$4>J27,"Overdue","Upcoming")),IF(N(O27)>=1,"Done",IF($D$4<I27,"Not started",IF($D$4>J27,"Late",IF(N(O27)+0.1<($D$4-I27+1)/(J27-I27+1),"Behind","On track")))))) -> Not started | Q27: =IF(C27="Break","",ROUND((IF(N27<>"",N27,J27)-H27)/7,1)) -> -3 | R27: =IF(C27="Milestone",IF(N27<>"","✓",""),IF(AND(C27="Task",N(O27)>=1),"✓","")) | S27: =IF(C27="Task",K27*N(O27),"") -> 0 | U27: =IF($C27="Milestone",IF(AND(U$7<=$I27,U$7+6>=$I27),"◆",""),IF(AND($C27="Task",$M27<>"",U$7<=IF($N27="",$D$4,$N27),U$7+6>=$M27),"●","")) | V27: =IF($C27="Milestone",IF(AND(V$7<=$I27,V$7+6>=$I27),"◆",""),IF(AND($C27="Task",$M27<>"",V$7<=IF($N27="",$D$4,$N27),V$7+6>=$M27),"●","")) | W27: =IF($C27="Milestone",IF(AND(W$7<=$I27,W$7+6>=$I27),"◆",""),IF(AND($C27="Task",$M27<>"",W$7<=IF($N27="",$D$4,$N27),W$7+6>=$M27),"●","")) | X27: =IF($C27="Milestone",IF(AND(X$7<=$I27,X$7+6>=$I27),"◆",""),IF(AND($C27="Task",$M27<>"",X$7<=IF($N27="",$D$4,$N27),X$7+6>=$M27),"●","")) | Y27: =IF($C27="Milestone",IF(AND(Y$7<=$I27,Y$7+6>=$I27),"◆",""),IF(AND($C27="Task",$M27<>"",Y$7<=IF($N27="",$D$4,$N27),Y$7+6>=$M27),"●","")) | Z27: =IF($C27="Milestone",IF(AND(Z$7<=$I27,Z$7+6>=$I27),"◆",""),IF(AND($C27="Task",$M27<>"",Z$7<=IF($N27="",$D$4,$N27),Z$7+6>=$M27),"●","")) | AA27: =IF($C27="Milestone",IF(AND(AA$7<=$I27,AA$7+6>=$I27),"◆",""),IF(AND($C27="Task",$M27<>"",AA$7<=IF($N27="",$D$4,$N27),AA$7+6>=$M27),"●","")) | AB27: =IF($C27="Milestone",IF(AND(AB$7<=$I27,AB$7+6>=$I27),"◆",""),IF(AND($C27="Task",$M27<>"",AB$7<=IF($N27="",$D$4,$N27),AB$7+6>=$M27),"●","")) | ... AZ27: =IF($C27="Milestone",IF(AND(AZ$7<=$I27,AZ$7+6>=$I27),"◆",""),IF(AND($C27="Task",$M27<>"",AZ$7<=IF($N27="",$D$4,$N27),AZ$7+6>=$M27),"●",""))
A28: S6 | B28: DP state count and timing in Python | C28: Task | D28: O6 | E28: S4 | F28: No | G28: 46363 | H28: 46367 | I28: 46335 | J28: 46339 | K28: =IF(C28="Task",ROUND((J28-I28+3)/7,0),"") -> 1 | L28: 1 | P28: =IF(C28="Break","",IF(C28="Milestone",IF(N28<>"","Done",IF($D$4>J28,"Overdue","Upcoming")),IF(N(O28)>=1,"Done",IF($D$4<I28,"Not started",IF($D$4>J28,"Late",IF(N(O28)+0.1<($D$4-I28+1)/(J28-I28+1),"Behind","On track")))))) -> Not started | Q28: =IF(C28="Break","",ROUND((IF(N28<>"",N28,J28)-H28)/7,1)) -> -4 | R28: =IF(C28="Milestone",IF(N28<>"","✓",""),IF(AND(C28="Task",N(O28)>=1),"✓","")) | S28: =IF(C28="Task",K28*N(O28),"") -> 0 | U28: =IF($C28="Milestone",IF(AND(U$7<=$I28,U$7+6>=$I28),"◆",""),IF(AND($C28="Task",$M28<>"",U$7<=IF($N28="",$D$4,$N28),U$7+6>=$M28),"●","")) | V28: =IF($C28="Milestone",IF(AND(V$7<=$I28,V$7+6>=$I28),"◆",""),IF(AND($C28="Task",$M28<>"",V$7<=IF($N28="",$D$4,$N28),V$7+6>=$M28),"●","")) | W28: =IF($C28="Milestone",IF(AND(W$7<=$I28,W$7+6>=$I28),"◆",""),IF(AND($C28="Task",$M28<>"",W$7<=IF($N28="",$D$4,$N28),W$7+6>=$M28),"●","")) | X28: =IF($C28="Milestone",IF(AND(X$7<=$I28,X$7+6>=$I28),"◆",""),IF(AND($C28="Task",$M28<>"",X$7<=IF($N28="",$D$4,$N28),X$7+6>=$M28),"●","")) | Y28: =IF($C28="Milestone",IF(AND(Y$7<=$I28,Y$7+6>=$I28),"◆",""),IF(AND($C28="Task",$M28<>"",Y$7<=IF($N28="",$D$4,$N28),Y$7+6>=$M28),"●","")) | Z28: =IF($C28="Milestone",IF(AND(Z$7<=$I28,Z$7+6>=$I28),"◆",""),IF(AND($C28="Task",$M28<>"",Z$7<=IF($N28="",$D$4,$N28),Z$7+6>=$M28),"●","")) | AA28: =IF($C28="Milestone",IF(AND(AA$7<=$I28,AA$7+6>=$I28),"◆",""),IF(AND($C28="Task",$M28<>"",AA$7<=IF($N28="",$D$4,$N28),AA$7+6>=$M28),"●","")) | AB28: =IF($C28="Milestone",IF(AND(AB$7<=$I28,AB$7+6>=$I28),"◆",""),IF(AND($C28="Task",$M28<>"",AB$7<=IF($N28="",$D$4,$N28),AB$7+6>=$M28),"●","")) | ... AZ28: =IF($C28="Milestone",IF(AND(AZ$7<=$I28,AZ$7+6>=$I28),"◆",""),IF(AND($C28="Task",$M28<>"",AZ$7<=IF($N28="",$D$4,$N28),AZ$7+6>=$M28),"●",""))
A29: S7 | B29: Baseline forecasters and first results | C29: Task | D29: O5 | E29: S2 | F29: No | G29: 46370 | H29: 46374 | I29: 46342 | J29: 46346 | K29: =IF(C29="Task",ROUND((J29-I29+3)/7,0),"") -> 1 | L29: 5 | P29: =IF(C29="Break","",IF(C29="Milestone",IF(N29<>"","Done",IF($D$4>J29,"Overdue","Upcoming")),IF(N(O29)>=1,"Done",IF($D$4<I29,"Not started",IF($D$4>J29,"Late",IF(N(O29)+0.1<($D$4-I29+1)/(J29-I29+1),"Behind","On track")))))) -> Not started | Q29: =IF(C29="Break","",ROUND((IF(N29<>"",N29,J29)-H29)/7,1)) -> -4 | R29: =IF(C29="Milestone",IF(N29<>"","✓",""),IF(AND(C29="Task",N(O29)>=1),"✓","")) | S29: =IF(C29="Task",K29*N(O29),"") -> 0 | U29: =IF($C29="Milestone",IF(AND(U$7<=$I29,U$7+6>=$I29),"◆",""),IF(AND($C29="Task",$M29<>"",U$7<=IF($N29="",$D$4,$N29),U$7+6>=$M29),"●","")) | V29: =IF($C29="Milestone",IF(AND(V$7<=$I29,V$7+6>=$I29),"◆",""),IF(AND($C29="Task",$M29<>"",V$7<=IF($N29="",$D$4,$N29),V$7+6>=$M29),"●","")) | W29: =IF($C29="Milestone",IF(AND(W$7<=$I29,W$7+6>=$I29),"◆",""),IF(AND($C29="Task",$M29<>"",W$7<=IF($N29="",$D$4,$N29),W$7+6>=$M29),"●","")) | X29: =IF($C29="Milestone",IF(AND(X$7<=$I29,X$7+6>=$I29),"◆",""),IF(AND($C29="Task",$M29<>"",X$7<=IF($N29="",$D$4,$N29),X$7+6>=$M29),"●","")) | Y29: =IF($C29="Milestone",IF(AND(Y$7<=$I29,Y$7+6>=$I29),"◆",""),IF(AND($C29="Task",$M29<>"",Y$7<=IF($N29="",$D$4,$N29),Y$7+6>=$M29),"●","")) | Z29: =IF($C29="Milestone",IF(AND(Z$7<=$I29,Z$7+6>=$I29),"◆",""),IF(AND($C29="Task",$M29<>"",Z$7<=IF($N29="",$D$4,$N29),Z$7+6>=$M29),"●","")) | AA29: =IF($C29="Milestone",IF(AND(AA$7<=$I29,AA$7+6>=$I29),"◆",""),IF(AND($C29="Task",$M29<>"",AA$7<=IF($N29="",$D$4,$N29),AA$7+6>=$M29),"●","")) | AB29: =IF($C29="Milestone",IF(AND(AB$7<=$I29,AB$7+6>=$I29),"◆",""),IF(AND($C29="Task",$M29<>"",AB$7<=IF($N29="",$D$4,$N29),AB$7+6>=$M29),"●","")) | ... AZ29: =IF($C29="Milestone",IF(AND(AZ$7<=$I29,AZ$7+6>=$I29),"◆",""),IF(AND($C29="Task",$M29<>"",AZ$7<=IF($N29="",$D$4,$N29),AZ$7+6>=$M29),"●",""))
A30: S8 | B30: LightGBM forecaster against baselines (T5) | C30: Task | D30: O5 | E30: S7 | F30: No | G30: 46412 | H30: 46416 | I30: 46349 | J30: 46360 | K30: =IF(C30="Task",ROUND((J30-I30+3)/7,0),"") -> 2 | L30: 1 | P30: =IF(C30="Break","",IF(C30="Milestone",IF(N30<>"","Done",IF($D$4>J30,"Overdue","Upcoming")),IF(N(O30)>=1,"Done",IF($D$4<I30,"Not started",IF($D$4>J30,"Late",IF(N(O30)+0.1<($D$4-I30+1)/(J30-I30+1),"Behind","On track")))))) -> Not started | Q30: =IF(C30="Break","",ROUND((IF(N30<>"",N30,J30)-H30)/7,1)) -> -8 | R30: =IF(C30="Milestone",IF(N30<>"","✓",""),IF(AND(C30="Task",N(O30)>=1),"✓","")) | S30: =IF(C30="Task",K30*N(O30),"") -> 0 | U30: =IF($C30="Milestone",IF(AND(U$7<=$I30,U$7+6>=$I30),"◆",""),IF(AND($C30="Task",$M30<>"",U$7<=IF($N30="",$D$4,$N30),U$7+6>=$M30),"●","")) | V30: =IF($C30="Milestone",IF(AND(V$7<=$I30,V$7+6>=$I30),"◆",""),IF(AND($C30="Task",$M30<>"",V$7<=IF($N30="",$D$4,$N30),V$7+6>=$M30),"●","")) | W30: =IF($C30="Milestone",IF(AND(W$7<=$I30,W$7+6>=$I30),"◆",""),IF(AND($C30="Task",$M30<>"",W$7<=IF($N30="",$D$4,$N30),W$7+6>=$M30),"●","")) | X30: =IF($C30="Milestone",IF(AND(X$7<=$I30,X$7+6>=$I30),"◆",""),IF(AND($C30="Task",$M30<>"",X$7<=IF($N30="",$D$4,$N30),X$7+6>=$M30),"●","")) | Y30: =IF($C30="Milestone",IF(AND(Y$7<=$I30,Y$7+6>=$I30),"◆",""),IF(AND($C30="Task",$M30<>"",Y$7<=IF($N30="",$D$4,$N30),Y$7+6>=$M30),"●","")) | Z30: =IF($C30="Milestone",IF(AND(Z$7<=$I30,Z$7+6>=$I30),"◆",""),IF(AND($C30="Task",$M30<>"",Z$7<=IF($N30="",$D$4,$N30),Z$7+6>=$M30),"●","")) | AA30: =IF($C30="Milestone",IF(AND(AA$7<=$I30,AA$7+6>=$I30),"◆",""),IF(AND($C30="Task",$M30<>"",AA$7<=IF($N30="",$D$4,$N30),AA$7+6>=$M30),"●","")) | AB30: =IF($C30="Milestone",IF(AND(AB$7<=$I30,AB$7+6>=$I30),"◆",""),IF(AND($C30="Task",$M30<>"",AB$7<=IF($N30="",$D$4,$N30),AB$7+6>=$M30),"●","")) | ... AZ30: =IF($C30="Milestone",IF(AND(AZ$7<=$I30,AZ$7+6>=$I30),"◆",""),IF(AND($C30="Task",$M30<>"",AZ$7<=IF($N30="",$D$4,$N30),AZ$7+6>=$M30),"●",""))
A31: S9 | B31: O5 met: forecaster results | C31: Milestone | D31: O5 | E31: S8 | F31: No | G31: 46416 | H31: 46416 | I31: 46360 | J31: 46360 | K31: =IF(C31="Task",ROUND((J31-I31+3)/7,0),"") | P31: =IF(C31="Break","",IF(C31="Milestone",IF(N31<>"","Done",IF($D$4>J31,"Overdue","Upcoming")),IF(N(O31)>=1,"Done",IF($D$4<I31,"Not started",IF($D$4>J31,"Late",IF(N(O31)+0.1<($D$4-I31+1)/(J31-I31+1),"Behind","On track")))))) -> Upcoming | Q31: =IF(C31="Break","",ROUND((IF(N31<>"",N31,J31)-H31)/7,1)) -> -8 | R31: =IF(C31="Milestone",IF(N31<>"","✓",""),IF(AND(C31="Task",N(O31)>=1),"✓","")) | S31: =IF(C31="Task",K31*N(O31),"") | U31: =IF($C31="Milestone",IF(AND(U$7<=$I31,U$7+6>=$I31),"◆",""),IF(AND($C31="Task",$M31<>"",U$7<=IF($N31="",$D$4,$N31),U$7+6>=$M31),"●","")) | V31: =IF($C31="Milestone",IF(AND(V$7<=$I31,V$7+6>=$I31),"◆",""),IF(AND($C31="Task",$M31<>"",V$7<=IF($N31="",$D$4,$N31),V$7+6>=$M31),"●","")) | W31: =IF($C31="Milestone",IF(AND(W$7<=$I31,W$7+6>=$I31),"◆",""),IF(AND($C31="Task",$M31<>"",W$7<=IF($N31="",$D$4,$N31),W$7+6>=$M31),"●","")) | X31: =IF($C31="Milestone",IF(AND(X$7<=$I31,X$7+6>=$I31),"◆",""),IF(AND($C31="Task",$M31<>"",X$7<=IF($N31="",$D$4,$N31),X$7+6>=$M31),"●","")) | Y31: =IF($C31="Milestone",IF(AND(Y$7<=$I31,Y$7+6>=$I31),"◆",""),IF(AND($C31="Task",$M31<>"",Y$7<=IF($N31="",$D$4,$N31),Y$7+6>=$M31),"●","")) | Z31: =IF($C31="Milestone",IF(AND(Z$7<=$I31,Z$7+6>=$I31),"◆",""),IF(AND($C31="Task",$M31<>"",Z$7<=IF($N31="",$D$4,$N31),Z$7+6>=$M31),"●","")) | AA31: =IF($C31="Milestone",IF(AND(AA$7<=$I31,AA$7+6>=$I31),"◆",""),IF(AND($C31="Task",$M31<>"",AA$7<=IF($N31="",$D$4,$N31),AA$7+6>=$M31),"●","")) -> ◆ | AB31: =IF($C31="Milestone",IF(AND(AB$7<=$I31,AB$7+6>=$I31),"◆",""),IF(AND($C31="Task",$M31<>"",AB$7<=IF($N31="",$D$4,$N31),AB$7+6>=$M31),"●","")) | ... AZ31: =IF($C31="Milestone",IF(AND(AZ$7<=$I31,AZ$7+6>=$I31),"◆",""),IF(AND($C31="Task",$M31<>"",AZ$7<=IF($N31="",$D$4,$N31),AZ$7+6>=$M31),"●",""))
B32: Hardware | C32: Group
A33: H1 | B33: Order chips and parts via technician (by Wed 28 Oct, 17:00) | C33: Task | F33: Yes | G33: 46314 | H33: 46325 | I33: 46314 | J33: 46325 | K33: =IF(C33="Task",ROUND((J33-I33+3)/7,0),"") -> 2 | L33: 0 | P33: =IF(C33="Break","",IF(C33="Milestone",IF(N33<>"","Done",IF($D$4>J33,"Overdue","Upcoming")),IF(N(O33)>=1,"Done",IF($D$4<I33,"Not started",IF($D$4>J33,"Late",IF(N(O33)+0.1<($D$4-I33+1)/(J33-I33+1),"Behind","On track")))))) -> Behind | Q33: =IF(C33="Break","",ROUND((IF(N33<>"",N33,J33)-H33)/7,1)) -> 0 | R33: =IF(C33="Milestone",IF(N33<>"","✓",""),IF(AND(C33="Task",N(O33)>=1),"✓","")) | S33: =IF(C33="Task",K33*N(O33),"") -> 0 | U33: =IF($C33="Milestone",IF(AND(U$7<=$I33,U$7+6>=$I33),"◆",""),IF(AND($C33="Task",$M33<>"",U$7<=IF($N33="",$D$4,$N33),U$7+6>=$M33),"●","")) | V33: =IF($C33="Milestone",IF(AND(V$7<=$I33,V$7+6>=$I33),"◆",""),IF(AND($C33="Task",$M33<>"",V$7<=IF($N33="",$D$4,$N33),V$7+6>=$M33),"●","")) | W33: =IF($C33="Milestone",IF(AND(W$7<=$I33,W$7+6>=$I33),"◆",""),IF(AND($C33="Task",$M33<>"",W$7<=IF($N33="",$D$4,$N33),W$7+6>=$M33),"●","")) | X33: =IF($C33="Milestone",IF(AND(X$7<=$I33,X$7+6>=$I33),"◆",""),IF(AND($C33="Task",$M33<>"",X$7<=IF($N33="",$D$4,$N33),X$7+6>=$M33),"●","")) | Y33: =IF($C33="Milestone",IF(AND(Y$7<=$I33,Y$7+6>=$I33),"◆",""),IF(AND($C33="Task",$M33<>"",Y$7<=IF($N33="",$D$4,$N33),Y$7+6>=$M33),"●","")) | Z33: =IF($C33="Milestone",IF(AND(Z$7<=$I33,Z$7+6>=$I33),"◆",""),IF(AND($C33="Task",$M33<>"",Z$7<=IF($N33="",$D$4,$N33),Z$7+6>=$M33),"●","")) | AA33: =IF($C33="Milestone",IF(AND(AA$7<=$I33,AA$7+6>=$I33),"◆",""),IF(AND($C33="Task",$M33<>"",AA$7<=IF($N33="",$D$4,$N33),AA$7+6>=$M33),"●","")) | AB33: =IF($C33="Milestone",IF(AND(AB$7<=$I33,AB$7+6>=$I33),"◆",""),IF(AND($C33="Task",$M33<>"",AB$7<=IF($N33="",$D$4,$N33),AB$7+6>=$M33),"●","")) | ... AZ33: =IF($C33="Milestone",IF(AND(AZ$7<=$I33,AZ$7+6>=$I33),"◆",""),IF(AND($C33="Task",$M33<>"",AZ$7<=IF($N33="",$D$4,$N33),AZ$7+6>=$M33),"●",""))
A34: H2 | B34: Proteus practice task | C34: Task | F34: No | G34: 46321 | H34: 46325 | I34: 46314 | J34: 46325 | K34: =IF(C34="Task",ROUND((J34-I34+3)/7,0),"") -> 2 | L34: 1 | P34: =IF(C34="Break","",IF(C34="Milestone",IF(N34<>"","Done",IF($D$4>J34,"Overdue","Upcoming")),IF(N(O34)>=1,"Done",IF($D$4<I34,"Not started",IF($D$4>J34,"Late",IF(N(O34)+0.1<($D$4-I34+1)/(J34-I34+1),"Behind","On track")))))) -> Behind | Q34: =IF(C34="Break","",ROUND((IF(N34<>"",N34,J34)-H34)/7,1)) -> 0 | R34: =IF(C34="Milestone",IF(N34<>"","✓",""),IF(AND(C34="Task",N(O34)>=1),"✓","")) | S34: =IF(C34="Task",K34*N(O34),"") -> 0 | U34: =IF($C34="Milestone",IF(AND(U$7<=$I34,U$7+6>=$I34),"◆",""),IF(AND($C34="Task",$M34<>"",U$7<=IF($N34="",$D$4,$N34),U$7+6>=$M34),"●","")) | V34: =IF($C34="Milestone",IF(AND(V$7<=$I34,V$7+6>=$I34),"◆",""),IF(AND($C34="Task",$M34<>"",V$7<=IF($N34="",$D$4,$N34),V$7+6>=$M34),"●","")) | W34: =IF($C34="Milestone",IF(AND(W$7<=$I34,W$7+6>=$I34),"◆",""),IF(AND($C34="Task",$M34<>"",W$7<=IF($N34="",$D$4,$N34),W$7+6>=$M34),"●","")) | X34: =IF($C34="Milestone",IF(AND(X$7<=$I34,X$7+6>=$I34),"◆",""),IF(AND($C34="Task",$M34<>"",X$7<=IF($N34="",$D$4,$N34),X$7+6>=$M34),"●","")) | Y34: =IF($C34="Milestone",IF(AND(Y$7<=$I34,Y$7+6>=$I34),"◆",""),IF(AND($C34="Task",$M34<>"",Y$7<=IF($N34="",$D$4,$N34),Y$7+6>=$M34),"●","")) | Z34: =IF($C34="Milestone",IF(AND(Z$7<=$I34,Z$7+6>=$I34),"◆",""),IF(AND($C34="Task",$M34<>"",Z$7<=IF($N34="",$D$4,$N34),Z$7+6>=$M34),"●","")) | AA34: =IF($C34="Milestone",IF(AND(AA$7<=$I34,AA$7+6>=$I34),"◆",""),IF(AND($C34="Task",$M34<>"",AA$7<=IF($N34="",$D$4,$N34),AA$7+6>=$M34),"●","")) | AB34: =IF($C34="Milestone",IF(AND(AB$7<=$I34,AB$7+6>=$I34),"◆",""),IF(AND($C34="Task",$M34<>"",AB$7<=IF($N34="",$D$4,$N34),AB$7+6>=$M34),"●","")) | ... AZ34: =IF($C34="Milestone",IF(AND(AZ$7<=$I34,AZ$7+6>=$I34),"◆",""),IF(AND($C34="Task",$M34<>"",AZ$7<=IF($N34="",$D$4,$N34),AZ$7+6>=$M34),"●",""))
A35: H3 | B35: Sensing PCB: schematic in Proteus, technician review | C35: Task | D35: O2 | E35: H1 | F35: Yes | G35: 46328 | H35: 46332 | I35: 46321 | J35: 46325 | K35: =IF(C35="Task",ROUND((J35-I35+3)/7,0),"") -> 1 | L35: 0 | P35: =IF(C35="Break","",IF(C35="Milestone",IF(N35<>"","Done",IF($D$4>J35,"Overdue","Upcoming")),IF(N(O35)>=1,"Done",IF($D$4<I35,"Not started",IF($D$4>J35,"Late",IF(N(O35)+0.1<($D$4-I35+1)/(J35-I35+1),"Behind","On track")))))) -> Not started | Q35: =IF(C35="Break","",ROUND((IF(N35<>"",N35,J35)-H35)/7,1)) -> -1 | R35: =IF(C35="Milestone",IF(N35<>"","✓",""),IF(AND(C35="Task",N(O35)>=1),"✓","")) | S35: =IF(C35="Task",K35*N(O35),"") -> 0 | U35: =IF($C35="Milestone",IF(AND(U$7<=$I35,U$7+6>=$I35),"◆",""),IF(AND($C35="Task",$M35<>"",U$7<=IF($N35="",$D$4,$N35),U$7+6>=$M35),"●","")) | V35: =IF($C35="Milestone",IF(AND(V$7<=$I35,V$7+6>=$I35),"◆",""),IF(AND($C35="Task",$M35<>"",V$7<=IF($N35="",$D$4,$N35),V$7+6>=$M35),"●","")) | W35: =IF($C35="Milestone",IF(AND(W$7<=$I35,W$7+6>=$I35),"◆",""),IF(AND($C35="Task",$M35<>"",W$7<=IF($N35="",$D$4,$N35),W$7+6>=$M35),"●","")) | X35: =IF($C35="Milestone",IF(AND(X$7<=$I35,X$7+6>=$I35),"◆",""),IF(AND($C35="Task",$M35<>"",X$7<=IF($N35="",$D$4,$N35),X$7+6>=$M35),"●","")) | Y35: =IF($C35="Milestone",IF(AND(Y$7<=$I35,Y$7+6>=$I35),"◆",""),IF(AND($C35="Task",$M35<>"",Y$7<=IF($N35="",$D$4,$N35),Y$7+6>=$M35),"●","")) | Z35: =IF($C35="Milestone",IF(AND(Z$7<=$I35,Z$7+6>=$I35),"◆",""),IF(AND($C35="Task",$M35<>"",Z$7<=IF($N35="",$D$4,$N35),Z$7+6>=$M35),"●","")) | AA35: =IF($C35="Milestone",IF(AND(AA$7<=$I35,AA$7+6>=$I35),"◆",""),IF(AND($C35="Task",$M35<>"",AA$7<=IF($N35="",$D$4,$N35),AA$7+6>=$M35),"●","")) | AB35: =IF($C35="Milestone",IF(AND(AB$7<=$I35,AB$7+6>=$I35),"◆",""),IF(AND($C35="Task",$M35<>"",AB$7<=IF($N35="",$D$4,$N35),AB$7+6>=$M35),"●","")) | ... AZ35: =IF($C35="Milestone",IF(AND(AZ$7<=$I35,AZ$7+6>=$I35),"◆",""),IF(AND($C35="Task",$M35<>"",AZ$7<=IF($N35="",$D$4,$N35),AZ$7+6>=$M35),"●",""))
A36: H4 | B36: Sensing PCB: layout, design-rule check, Tuesday submission | C36: Task | D36: O2 | E36: H3 | F36: Yes | G36: 46335 | H36: 46339 | I36: 46328 | J36: 46332 | K36: =IF(C36="Task",ROUND((J36-I36+3)/7,0),"") -> 1 | L36: 0 | P36: =IF(C36="Break","",IF(C36="Milestone",IF(N36<>"","Done",IF($D$4>J36,"Overdue","Upcoming")),IF(N(O36)>=1,"Done",IF($D$4<I36,"Not started",IF($D$4>J36,"Late",IF(N(O36)+0.1<($D$4-I36+1)/(J36-I36+1),"Behind","On track")))))) -> Not started | Q36: =IF(C36="Break","",ROUND((IF(N36<>"",N36,J36)-H36)/7,1)) -> -1 | R36: =IF(C36="Milestone",IF(N36<>"","✓",""),IF(AND(C36="Task",N(O36)>=1),"✓","")) | S36: =IF(C36="Task",K36*N(O36),"") -> 0 | U36: =IF($C36="Milestone",IF(AND(U$7<=$I36,U$7+6>=$I36),"◆",""),IF(AND($C36="Task",$M36<>"",U$7<=IF($N36="",$D$4,$N36),U$7+6>=$M36),"●","")) | V36: =IF($C36="Milestone",IF(AND(V$7<=$I36,V$7+6>=$I36),"◆",""),IF(AND($C36="Task",$M36<>"",V$7<=IF($N36="",$D$4,$N36),V$7+6>=$M36),"●","")) | W36: =IF($C36="Milestone",IF(AND(W$7<=$I36,W$7+6>=$I36),"◆",""),IF(AND($C36="Task",$M36<>"",W$7<=IF($N36="",$D$4,$N36),W$7+6>=$M36),"●","")) | X36: =IF($C36="Milestone",IF(AND(X$7<=$I36,X$7+6>=$I36),"◆",""),IF(AND($C36="Task",$M36<>"",X$7<=IF($N36="",$D$4,$N36),X$7+6>=$M36),"●","")) | Y36: =IF($C36="Milestone",IF(AND(Y$7<=$I36,Y$7+6>=$I36),"◆",""),IF(AND($C36="Task",$M36<>"",Y$7<=IF($N36="",$D$4,$N36),Y$7+6>=$M36),"●","")) | Z36: =IF($C36="Milestone",IF(AND(Z$7<=$I36,Z$7+6>=$I36),"◆",""),IF(AND($C36="Task",$M36<>"",Z$7<=IF($N36="",$D$4,$N36),Z$7+6>=$M36),"●","")) | AA36: =IF($C36="Milestone",IF(AND(AA$7<=$I36,AA$7+6>=$I36),"◆",""),IF(AND($C36="Task",$M36<>"",AA$7<=IF($N36="",$D$4,$N36),AA$7+6>=$M36),"●","")) | AB36: =IF($C36="Milestone",IF(AND(AB$7<=$I36,AB$7+6>=$I36),"◆",""),IF(AND($C36="Task",$M36<>"",AB$7<=IF($N36="",$D$4,$N36),AB$7+6>=$M36),"●","")) | ... AZ36: =IF($C36="Milestone",IF(AND(AZ$7<=$I36,AZ$7+6>=$I36),"◆",""),IF(AND($C36="Task",$M36<>"",AZ$7<=IF($N36="",$D$4,$N36),AZ$7+6>=$M36),"●",""))
A37: H5 | B37: Sensing PCB: assembly on the SMD station | C37: Task | D37: O2 | E37: H4 | F37: Yes | G37: 46342 | H37: 46346 | I37: 46335 | J37: 46339 | K37: =IF(C37="Task",ROUND((J37-I37+3)/7,0),"") -> 1 | L37: 0 | P37: =IF(C37="Break","",IF(C37="Milestone",IF(N37<>"","Done",IF($D$4>J37,"Overdue","Upcoming")),IF(N(O37)>=1,"Done",IF($D$4<I37,"Not started",IF($D$4>J37,"Late",IF(N(O37)+0.1<($D$4-I37+1)/(J37-I37+1),"Behind","On track")))))) -> Not started | Q37: =IF(C37="Break","",ROUND((IF(N37<>"",N37,J37)-H37)/7,1)) -> -1 | R37: =IF(C37="Milestone",IF(N37<>"","✓",""),IF(AND(C37="Task",N(O37)>=1),"✓","")) | S37: =IF(C37="Task",K37*N(O37),"") -> 0 | U37: =IF($C37="Milestone",IF(AND(U$7<=$I37,U$7+6>=$I37),"◆",""),IF(AND($C37="Task",$M37<>"",U$7<=IF($N37="",$D$4,$N37),U$7+6>=$M37),"●","")) | V37: =IF($C37="Milestone",IF(AND(V$7<=$I37,V$7+6>=$I37),"◆",""),IF(AND($C37="Task",$M37<>"",V$7<=IF($N37="",$D$4,$N37),V$7+6>=$M37),"●","")) | W37: =IF($C37="Milestone",IF(AND(W$7<=$I37,W$7+6>=$I37),"◆",""),IF(AND($C37="Task",$M37<>"",W$7<=IF($N37="",$D$4,$N37),W$7+6>=$M37),"●","")) | X37: =IF($C37="Milestone",IF(AND(X$7<=$I37,X$7+6>=$I37),"◆",""),IF(AND($C37="Task",$M37<>"",X$7<=IF($N37="",$D$4,$N37),X$7+6>=$M37),"●","")) | Y37: =IF($C37="Milestone",IF(AND(Y$7<=$I37,Y$7+6>=$I37),"◆",""),IF(AND($C37="Task",$M37<>"",Y$7<=IF($N37="",$D$4,$N37),Y$7+6>=$M37),"●","")) | Z37: =IF($C37="Milestone",IF(AND(Z$7<=$I37,Z$7+6>=$I37),"◆",""),IF(AND($C37="Task",$M37<>"",Z$7<=IF($N37="",$D$4,$N37),Z$7+6>=$M37),"●","")) | AA37: =IF($C37="Milestone",IF(AND(AA$7<=$I37,AA$7+6>=$I37),"◆",""),IF(AND($C37="Task",$M37<>"",AA$7<=IF($N37="",$D$4,$N37),AA$7+6>=$M37),"●","")) | AB37: =IF($C37="Milestone",IF(AND(AB$7<=$I37,AB$7+6>=$I37),"◆",""),IF(AND($C37="Task",$M37<>"",AB$7<=IF($N37="",$D$4,$N37),AB$7+6>=$M37),"●","")) | ... AZ37: =IF($C37="Milestone",IF(AND(AZ$7<=$I37,AZ$7+6>=$I37),"◆",""),IF(AND($C37="Task",$M37<>"",AZ$7<=IF($N37="",$D$4,$N37),AZ$7+6>=$M37),"●",""))
A38: H6 | B38: Sensing PCB: T2 calibration sweep | C38: Task | D38: O2 | E38: H5 | F38: Yes | G38: 46349 | H38: 46353 | I38: 46335 | J38: 46339 | K38: =IF(C38="Task",ROUND((J38-I38+3)/7,0),"") -> 1 | L38: 0 | P38: =IF(C38="Break","",IF(C38="Milestone",IF(N38<>"","Done",IF($D$4>J38,"Overdue","Upcoming")),IF(N(O38)>=1,"Done",IF($D$4<I38,"Not started",IF($D$4>J38,"Late",IF(N(O38)+0.1<($D$4-I38+1)/(J38-I38+1),"Behind","On track")))))) -> Not started | Q38: =IF(C38="Break","",ROUND((IF(N38<>"",N38,J38)-H38)/7,1)) -> -2 | R38: =IF(C38="Milestone",IF(N38<>"","✓",""),IF(AND(C38="Task",N(O38)>=1),"✓","")) | S38: =IF(C38="Task",K38*N(O38),"") -> 0 | U38: =IF($C38="Milestone",IF(AND(U$7<=$I38,U$7+6>=$I38),"◆",""),IF(AND($C38="Task",$M38<>"",U$7<=IF($N38="",$D$4,$N38),U$7+6>=$M38),"●","")) | V38: =IF($C38="Milestone",IF(AND(V$7<=$I38,V$7+6>=$I38),"◆",""),IF(AND($C38="Task",$M38<>"",V$7<=IF($N38="",$D$4,$N38),V$7+6>=$M38),"●","")) | W38: =IF($C38="Milestone",IF(AND(W$7<=$I38,W$7+6>=$I38),"◆",""),IF(AND($C38="Task",$M38<>"",W$7<=IF($N38="",$D$4,$N38),W$7+6>=$M38),"●","")) | X38: =IF($C38="Milestone",IF(AND(X$7<=$I38,X$7+6>=$I38),"◆",""),IF(AND($C38="Task",$M38<>"",X$7<=IF($N38="",$D$4,$N38),X$7+6>=$M38),"●","")) | Y38: =IF($C38="Milestone",IF(AND(Y$7<=$I38,Y$7+6>=$I38),"◆",""),IF(AND($C38="Task",$M38<>"",Y$7<=IF($N38="",$D$4,$N38),Y$7+6>=$M38),"●","")) | Z38: =IF($C38="Milestone",IF(AND(Z$7<=$I38,Z$7+6>=$I38),"◆",""),IF(AND($C38="Task",$M38<>"",Z$7<=IF($N38="",$D$4,$N38),Z$7+6>=$M38),"●","")) | AA38: =IF($C38="Milestone",IF(AND(AA$7<=$I38,AA$7+6>=$I38),"◆",""),IF(AND($C38="Task",$M38<>"",AA$7<=IF($N38="",$D$4,$N38),AA$7+6>=$M38),"●","")) | AB38: =IF($C38="Milestone",IF(AND(AB$7<=$I38,AB$7+6>=$I38),"◆",""),IF(AND($C38="Task",$M38<>"",AB$7<=IF($N38="",$D$4,$N38),AB$7+6>=$M38),"●","")) | ... AZ38: =IF($C38="Milestone",IF(AND(AZ$7<=$I38,AZ$7+6>=$I38),"◆",""),IF(AND($C38="Task",$M38<>"",AZ$7<=IF($N38="",$D$4,$N38),AZ$7+6>=$M38),"●",""))
A39: H7 | B39: O2 met: sensing PCB | C39: Milestone | D39: O2 | E39: H6 | F39: Yes | G39: 46353 | H39: 46353 | I39: 46339 | J39: 46339 | K39: =IF(C39="Task",ROUND((J39-I39+3)/7,0),"") | P39: =IF(C39="Break","",IF(C39="Milestone",IF(N39<>"","Done",IF($D$4>J39,"Overdue","Upcoming")),IF(N(O39)>=1,"Done",IF($D$4<I39,"Not started",IF($D$4>J39,"Late",IF(N(O39)+0.1<($D$4-I39+1)/(J39-I39+1),"Behind","On track")))))) -> Upcoming | Q39: =IF(C39="Break","",ROUND((IF(N39<>"",N39,J39)-H39)/7,1)) -> -2 | R39: =IF(C39="Milestone",IF(N39<>"","✓",""),IF(AND(C39="Task",N(O39)>=1),"✓","")) | S39: =IF(C39="Task",K39*N(O39),"") | U39: =IF($C39="Milestone",IF(AND(U$7<=$I39,U$7+6>=$I39),"◆",""),IF(AND($C39="Task",$M39<>"",U$7<=IF($N39="",$D$4,$N39),U$7+6>=$M39),"●","")) | V39: =IF($C39="Milestone",IF(AND(V$7<=$I39,V$7+6>=$I39),"◆",""),IF(AND($C39="Task",$M39<>"",V$7<=IF($N39="",$D$4,$N39),V$7+6>=$M39),"●","")) | W39: =IF($C39="Milestone",IF(AND(W$7<=$I39,W$7+6>=$I39),"◆",""),IF(AND($C39="Task",$M39<>"",W$7<=IF($N39="",$D$4,$N39),W$7+6>=$M39),"●","")) | X39: =IF($C39="Milestone",IF(AND(X$7<=$I39,X$7+6>=$I39),"◆",""),IF(AND($C39="Task",$M39<>"",X$7<=IF($N39="",$D$4,$N39),X$7+6>=$M39),"●","")) -> ◆ | Y39: =IF($C39="Milestone",IF(AND(Y$7<=$I39,Y$7+6>=$I39),"◆",""),IF(AND($C39="Task",$M39<>"",Y$7<=IF($N39="",$D$4,$N39),Y$7+6>=$M39),"●","")) | Z39: =IF($C39="Milestone",IF(AND(Z$7<=$I39,Z$7+6>=$I39),"◆",""),IF(AND($C39="Task",$M39<>"",Z$7<=IF($N39="",$D$4,$N39),Z$7+6>=$M39),"●","")) | AA39: =IF($C39="Milestone",IF(AND(AA$7<=$I39,AA$7+6>=$I39),"◆",""),IF(AND($C39="Task",$M39<>"",AA$7<=IF($N39="",$D$4,$N39),AA$7+6>=$M39),"●","")) | AB39: =IF($C39="Milestone",IF(AND(AB$7<=$I39,AB$7+6>=$I39),"◆",""),IF(AND($C39="Task",$M39<>"",AB$7<=IF($N39="",$D$4,$N39),AB$7+6>=$M39),"●","")) | ... AZ39: =IF($C39="Milestone",IF(AND(AZ$7<=$I39,AZ$7+6>=$I39),"◆",""),IF(AND($C39="Task",$M39<>"",AZ$7<=IF($N39="",$D$4,$N39),AZ$7+6>=$M39),"●",""))
A40: H8 | B40: Over-current trip on breadboard; switching schematic | C40: Task | D40: O4 | E40: H1 | F40: No | G40: 46342 | H40: 46346 | I40: 46328 | J40: 46339 | K40: =IF(C40="Task",ROUND((J40-I40+3)/7,0),"") -> 2 | L40: 1 | P40: =IF(C40="Break","",IF(C40="Milestone",IF(N40<>"","Done",IF($D$4>J40,"Overdue","Upcoming")),IF(N(O40)>=1,"Done",IF($D$4<I40,"Not started",IF($D$4>J40,"Late",IF(N(O40)+0.1<($D$4-I40+1)/(J40-I40+1),"Behind","On track")))))) -> Not started | Q40: =IF(C40="Break","",ROUND((IF(N40<>"",N40,J40)-H40)/7,1)) -> -1 | R40: =IF(C40="Milestone",IF(N40<>"","✓",""),IF(AND(C40="Task",N(O40)>=1),"✓","")) | S40: =IF(C40="Task",K40*N(O40),"") -> 0 | U40: =IF($C40="Milestone",IF(AND(U$7<=$I40,U$7+6>=$I40),"◆",""),IF(AND($C40="Task",$M40<>"",U$7<=IF($N40="",$D$4,$N40),U$7+6>=$M40),"●","")) | V40: =IF($C40="Milestone",IF(AND(V$7<=$I40,V$7+6>=$I40),"◆",""),IF(AND($C40="Task",$M40<>"",V$7<=IF($N40="",$D$4,$N40),V$7+6>=$M40),"●","")) | W40: =IF($C40="Milestone",IF(AND(W$7<=$I40,W$7+6>=$I40),"◆",""),IF(AND($C40="Task",$M40<>"",W$7<=IF($N40="",$D$4,$N40),W$7+6>=$M40),"●","")) | X40: =IF($C40="Milestone",IF(AND(X$7<=$I40,X$7+6>=$I40),"◆",""),IF(AND($C40="Task",$M40<>"",X$7<=IF($N40="",$D$4,$N40),X$7+6>=$M40),"●","")) | Y40: =IF($C40="Milestone",IF(AND(Y$7<=$I40,Y$7+6>=$I40),"◆",""),IF(AND($C40="Task",$M40<>"",Y$7<=IF($N40="",$D$4,$N40),Y$7+6>=$M40),"●","")) | Z40: =IF($C40="Milestone",IF(AND(Z$7<=$I40,Z$7+6>=$I40),"◆",""),IF(AND($C40="Task",$M40<>"",Z$7<=IF($N40="",$D$4,$N40),Z$7+6>=$M40),"●","")) | AA40: =IF($C40="Milestone",IF(AND(AA$7<=$I40,AA$7+6>=$I40),"◆",""),IF(AND($C40="Task",$M40<>"",AA$7<=IF($N40="",$D$4,$N40),AA$7+6>=$M40),"●","")) | AB40: =IF($C40="Milestone",IF(AND(AB$7<=$I40,AB$7+6>=$I40),"◆",""),IF(AND($C40="Task",$M40<>"",AB$7<=IF($N40="",$D$4,$N40),AB$7+6>=$M40),"●","")) | ... AZ40: =IF($C40="Milestone",IF(AND(AZ$7<=$I40,AZ$7+6>=$I40),"◆",""),IF(AND($C40="Task",$M40<>"",AZ$7<=IF($N40="",$D$4,$N40),AZ$7+6>=$M40),"●",""))
...

Sheet Change log
A1: Change log: every slip or re-plan, for the mid-term review
A2: The handbook asks for the original and revised plan, with slippages and how changes were decided. Add a row each time you move a planned date.
